<?xml version='1.0' encoding='utf-8'?>
<robot name="daadbot">
  
  <gazebo>
    <plugin filename="ign_ros2_control-system" name="ign_ros2_control::IgnitionROS2ControlPlugin">
      <parameters>/home/maryammahmood/xdaadbot_ws/install/daadbot_controller/share/daadbot_controller/config/effort_command_controller.yaml</parameters>
    </plugin>
  </gazebo>
  <ros2_control name="Manipulator" type="system">
    <hardware>
      <plugin>ign_ros2_control/IgnitionSystem</plugin>
    </hardware>
    <joint name="base_claw_joint1">
      <param name="mimic">gear1_joint</param>
      <param name="multiplier">-1</param>
      <state_interface name="position" />
      <state_interface name="velocity" />
      <state_interface name="effort" />
    </joint>
    <joint name="claw_joint1">
      <param name="mimic">base_claw_joint1</param>
      <param name="multiplier">1</param>
      <state_interface name="position" />
      <state_interface name="velocity" />
      <state_interface name="effort" />
    </joint>
    <joint name="gear2_joint">
      <param name="mimic">gear1_joint</param>
      <param name="multiplier">-1</param>
      <state_interface name="position" />
      <state_interface name="velocity" />
      <state_interface name="effort" />
    </joint>
    <joint name="base_claw_joint2">
      <param name="mimic">gear1_joint</param>
      <param name="multiplier">-1</param>
      <state_interface name="position" />
      <state_interface name="velocity" />
      <state_interface name="effort" />
    </joint>
    <joint name="claw_joint2">
      <param name="mimic">base_claw_joint2</param>
      <param name="multiplier">-1</param>
      <state_interface name="position" />
      <state_interface name="velocity" />
      <state_interface name="effort" />
    </joint>
    <joint name="joint_1">
      <command_interface name="effort">
        <param name="min">-18</param>
        <param name="max">18</param>
      </command_interface>
      <state_interface name="position" />
      <state_interface name="velocity" />
      <state_interface name="effort" />
    </joint>
    <joint name="joint_2">
      <command_interface name="effort">
        <param name="min">-39</param>
        <param name="max">39</param>
      </command_interface>
      <state_interface name="position" />
      <state_interface name="velocity" />
      <state_interface name="effort" />
    </joint>
    <joint name="joint_3">
      <command_interface name="effort">
        <param name="min">-18</param>
        <param name="max">18</param>
      </command_interface>
      <state_interface name="position" />
      <state_interface name="velocity" />
      <state_interface name="effort" />
    </joint>
    <joint name="joint_4">
      <command_interface name="effort">
        <param name="min">-18</param>
        <param name="max">18</param>
      </command_interface>
      <state_interface name="position" />
      <state_interface name="velocity" />
      <state_interface name="effort" />
    </joint>
    <joint name="joint_5">
      <command_interface name="effort">
        <param name="min">-5</param>
        <param name="max">5</param>
      </command_interface>
      <state_interface name="position" />
      <state_interface name="velocity" />
      <state_interface name="effort" />
    </joint>
    <joint name="joint_6">
      <command_interface name="effort">
        <param name="min">-5</param>
        <param name="max">5</param>
      </command_interface>
      <state_interface name="position" />
      <state_interface name="velocity" />
      <state_interface name="effort" />
    </joint>
    <joint name="joint_7">
      <command_interface name="effort">
        <param name="min">-5</param>
        <param name="max">5</param>
      </command_interface>
      <state_interface name="position" />
      <state_interface name="velocity" />
      <state_interface name="effort" />
    </joint>
    <joint name="gear1_joint">
      <command_interface name="effort">
        <param name="min">-180</param>
        <param name="max">180</param>
      </command_interface>
      <state_interface name="position" />
      <state_interface name="velocity" />
      <state_interface name="effort" />
    </joint>
  </ros2_control>
  <link name="table_top">
    <inertial>
      <origin rpy="0 0 0" xyz="-0.000629 -0.000566 0.516365" />
      <mass value="48.599542" />
      <inertia ixx="10.0" ixy="0" ixz="0" iyy="10.0" iyz="0" izz="10.0" />
    </inertial>
    <visual>
      <origin rpy="0 0 0" xyz="0 0 0" />
      <geometry>
        <box size="1.0 2.5 0.05" />
      </geometry>
      <material name="grey_base">
        <color rgba="0.81 0.81 0.63 1" />
      </material>
    </visual>
    <collision>
      <origin rpy="0 0 0" xyz="0 0 0" />
      <geometry>
        <box size="1.0 2.5 0.05" />
      </geometry>
    </collision>
    <visual>
      <origin rpy="0 0 0" xyz="0 1.2 0.675" />
      <geometry>
        <box size="0.2 0.2 1.35" />
      </geometry>
      <material name="wood_pillar_l">
        <color rgba="0.81 0.66 0.41 1" />
      </material>
    </visual>
    <collision>
      <origin rpy="0 0 0" xyz="0 1.2 0.675" />
      <geometry>
        <box size="0.2 0.2 1.35" />
      </geometry>
    </collision>
    <visual>
      <origin rpy="0 0 0" xyz="0 -1.2 0.675" />
      <geometry>
        <box size="0.2 0.2 1.35" />
      </geometry>
      <material name="wood_pillar_r">
        <color rgba="0.81 0.66 0.41 1" />
      </material>
    </visual>
    <collision>
      <origin rpy="0 0 0" xyz="0 -1.2 0.675" />
      <geometry>
        <box size="0.2 0.2 1.35" />
      </geometry>
    </collision>
    <visual>
      <origin rpy="0 0 0" xyz="0 0 1.35" />
      <geometry>
        <box size="0.4 2.5 0.1" />
      </geometry>
      <material name="wood_beam">
        <color rgba="0.81 0.66 0.41 1" />
      </material>
    </visual>
    <collision>
      <origin rpy="0 0 0" xyz="0 0 1.35" />
      <geometry>
        <box size="0.4 2.5 0.1" />
      </geometry>
    </collision>
  </link>
  <link name="table_link1">
    <inertial>
      <origin rpy="0 0 0" xyz="-0.000277 0.000799 0.000069" />
      <mass value="0.000985" />
      <inertia ixx="0.0001" ixy="0" ixz="0" iyy="0.0001" iyz="0" izz="0.0001" />
    </inertial>
  </link>
  <joint name="jnt1" type="fixed">
    <origin rpy="-1.5708 0 3.1416" xyz="0.005 0 1.28" />
    <parent link="table_top" />
    <child link="table_link1" />
    <axis xyz="0 0 0" />
  </joint>
  
  <link name="world" />
  
  <joint name="table_joint" type="fixed">
    <parent link="world" />
    <child link="table_top" />
    <origin rpy="0 0 0" xyz="0 0 0" />
    
  </joint>
  
  <joint name="base_joint" type="fixed">
    <parent link="table_top" />
    <child link="base_link" />
    <origin rpy="0 3.14 0" xyz="0.000 0.0 1.285" />
    
    
    
  </joint>
  <link name="base_link">
    <inertial>
      <origin rpy="0 0 0" xyz="-0.002484 -0.001242 0.003455" />
      <mass value="7.080898" />
      <inertia ixx="0.0466171750852481" ixy="0.00010076855342015" ixz="5.14819747192778E-08" iyy="0.0464821203083076" iyz="-1.44621889265211E-07" izz="0.0929840869855057" />
    </inertial>
    <visual>
      <origin rpy="0 0 0" xyz="0 0 0" />
      <geometry>
        <mesh filename="package://daadbot_desc/meshes/base_link.STL" />
      </geometry>
      <material name="">
        <color rgba="1 1 1 1" />
      </material>
    </visual>
    <collision>
      <origin rpy="0 0 0" xyz="0 0 0" />
      <geometry>
        <mesh filename="package://daadbot_desc/meshes/base_link.STL" />
      </geometry>
    </collision>
  </link>
  <link name="Link_1">
    <inertial>
      <origin rpy="0 0 3.14" xyz="0.022082 0.000889 0.076632" />
      <mass value="2.290365" />
      <inertia ixx="0.00332922517000865" ixy="1.64875308454708E-07" ixz="-0.000433929392474112" iyy="0.00524724735039028" iyz="2.38505609352415E-07" izz="0.00419520671173006" />
    </inertial>
    <visual>
      <origin rpy="0 0 0" xyz="0 0 0" />
      <geometry>
        <mesh filename="package://daadbot_desc/meshes/Link_1.STL" />
      </geometry>
      <material name="">
        <color rgba="0.329 0.322 0.302 1" />
      </material>
    </visual>
    <collision>
      <origin rpy="0 0 0" xyz="0 0 0" />
      <geometry>
        <mesh filename="package://daadbot_desc/meshes/Link_1.STL" />
      </geometry>
    </collision>
  </link>
  <joint name="joint_1" type="revolute">
    <origin rpy="0 0 0" xyz="-0.0029638 -0.0015759 0.04796" />
    <parent link="base_link" />
    <child link="Link_1" />
    <axis xyz="0 0 -1" />
    <limit effort="40.0" lower="-3.2" upper="3.2" velocity="1.2" />
    <dynamics damping="0.3" friction="0.0" />
  </joint>
  <gazebo reference="joint_1">
    <sensor name="ft_sensor_joint_1" type="force_torque">
      <always_on>true</always_on>
      <update_rate>1000</update_rate>
      <force_torque>
        <frame>child</frame>
        <measure_direction>child_to_parent</measure_direction>
      </force_torque>
      <pose>0 0 0 0 0 0</pose>
    </sensor>
  </gazebo>
  <link name="Link_2">
    <inertial>
      <origin rpy="0 0 0" xyz="0.121005 0.000209 -0.046027" />
      <mass value="2.366636" />
      <inertia ixx="0.00389001580470153" ixy="1.8291659115195E-06" ixz="2.04233321611583E-07" iyy="0.00259728697678572" iyz="3.29392581309982E-08" izz="0.00312685277067708" />
    </inertial>
    <visual>
      <origin rpy="0 0 0" xyz="0 0 0" />
      <geometry>
        <mesh filename="package://daadbot_desc/meshes/Link_2.STL" />
      </geometry>
      <material name="">
        <color rgba="1 1 1 1" />
      </material>
    </visual>
    <collision>
      <origin rpy="0 0 0" xyz="0 0 0" />
      <geometry>
        <mesh filename="package://daadbot_desc/meshes/Link_2.STL" />
      </geometry>
    </collision>
  </link>
  <joint name="joint_2" type="revolute">
    <origin rpy="1.57 -1.57 0" xyz="0.0400000000000002 -0.050000000000002 0.114463048454132" />
    <parent link="Link_1" />
    <child link="Link_2" />
    <axis xyz="0 0 -1" />
    <limit effort="40.0" lower="-1.745" upper="1.745" velocity="1.2" />
    <dynamics damping="0.3" friction="0.0" />
    <sensor name="force_torque" type="force_torque">
      <update_rate>30</update_rate>
    </sensor>
  </joint>
  <link name="Link_3">
    <inertial>
      <origin rpy="0 0 0" xyz="-0.004696 -0.000024 0.046359" />
      <mass value="1.295515" />
      <inertia ixx="0.00206983011422612" ixy="9.27500479472452E-08" ixz="3.38378548754623E-06" iyy="0.00129565231901482" iyz="2.88989653562542E-07" izz="0.00156994991003151" />
    </inertial>
    <visual>
      <origin rpy="0 0 0" xyz="0 0 0" />
      <geometry>
        <mesh filename="package://daadbot_desc/meshes/Link_3.STL" />
      </geometry>
      <material name="">
        <color rgba="0.329 0.322 0.302 1" />
      </material>
    </visual>
    <collision>
      <origin rpy="0 0 0" xyz="0 0 0" />
      <geometry>
        <mesh filename="package://daadbot_desc/meshes/Link_3.STL" />
      </geometry>
    </collision>
  </link>
  <joint name="joint_3" type="revolute">
    <origin rpy="0 1.5707963267949 0" xyz="0.234499999999998 0 -0.0495000000000002" />
    <parent link="Link_2" />
    <child link="Link_3" />
    <axis xyz="0 0 -1" />
    <limit effort="40.0" lower="-3.2" upper="3.2" velocity="1.2" />
    <dynamics damping="0.3" friction="0.0" />
  </joint>
  <link name="Link_4">
    <inertial>
      <origin rpy="0 0 0" xyz="-0.109540 -0.000145 0.036783" />
      <mass value="2.516984" />
      <inertia ixx="0.00308017562479927" ixy="2.47453551729311E-06" ixz="-7.09348932448939E-07" iyy="0.00238129778603005" iyz="-7.47320677385655E-07" izz="0.00293128138362422" />
    </inertial>
    <visual>
      <origin rpy="0 0 0" xyz="0 0 0" />
      <geometry>
        <mesh filename="package://daadbot_desc/meshes/Link_4.STL" />
      </geometry>
      <material name="">
        <color rgba="1 1 1 1" />
      </material>
    </visual>
    <collision>
      <origin rpy="0 0 0" xyz="0 0 0" />
      <geometry>
        <mesh filename="package://daadbot_desc/meshes/Link_4.STL" />
      </geometry>
    </collision>
  </link>
  <joint name="joint_4" type="revolute">
    <origin rpy="0 1.5707963267949 0" xyz="-0.0324999999999996 0 0.0750000000000004" />
    <parent link="Link_3" />
    <child link="Link_4" />
    <axis xyz="0 0 -1" />
    <limit effort="40.0" lower="-1.745" upper="1.745" velocity="1.2" />
    <dynamics damping="0.3" friction="0.0" />
  </joint>
  <link name="Link_5">
    <inertial>
      <origin rpy="3.14 0 0" xyz="0.006327 0.000038 0.047318" />
      <mass value="1.280752" />
      <inertia ixx="0.00112308173661534" ixy="1.28316182440177E-06" ixz="-8.91005390036956E-07" iyy="0.000690097277055795" iyz="-3.23958303943101E-07" izz="0.000815216487439054" />
    </inertial>
    <visual>
      <origin rpy="0 0 0" xyz="0 0 0" />
      <geometry>
        <mesh filename="package://daadbot_desc/meshes/Link_5.STL" />
      </geometry>
      <material name="">
        <color rgba="0.329 0.322 0.302 1" />
      </material>
    </visual>
    <collision>
      <origin rpy="0 0 0" xyz="0 0 0" />
      <geometry>
        <mesh filename="package://daadbot_desc/meshes/Link_5.STL" />
      </geometry>
    </collision>
  </link>
  <joint name="joint_5" type="revolute">
    <origin rpy="3.14159265358979 1.5707963267949 0" xyz="-0.2284999036789 0 0.0330000000000004" />
    <parent link="Link_4" />
    <child link="Link_5" />
    <axis xyz="0 0 -1" />
    <limit effort="15" lower="-3.2" upper="3.4" velocity="1.2" />
    <dynamics damping="0.3" friction="0.0" />
  </joint>
  <link name="Link_6">
    <inertial>
      <origin rpy="0 0 0" xyz="-0.053412 0.000043 0.028306" />
      <mass value="1.226669" />
      <inertia ixx="0.000961791856097317" ixy="1.00752377127578E-06" ixz="-2.55794494605017E-06" iyy="0.000676134530899485" iyz="-2.71811927605635E-06" izz="0.00084422746855334" />
    </inertial>
    <visual>
      <origin rpy="0 0 0" xyz="0 0 0" />
      <geometry>
        <mesh filename="package://daadbot_desc/meshes/link_6.STL" />
      </geometry>
      <material name="">
        <color rgba="1 1 1 1" />
      </material>
    </visual>
    <collision>
      <origin rpy="0 0 0" xyz="0 0 0" />
      <geometry>
        <mesh filename="package://daadbot_desc/meshes/link_6.STL" />
      </geometry>
    </collision>
  </link>
  <joint name="joint_6" type="revolute">
    <origin rpy="-1.57 1.57 -1.57" xyz="-0.0265000104908596 0 0.0575000000000075" />
    <parent link="Link_5" />
    <child link="Link_6" />
    <axis xyz="0 0 -1" />
    <limit effort="15" lower="-1.57" upper="1.57" velocity="1.2" />
    <dynamics damping="0.3" friction="0.0" />
  </joint>
  <link name="Link_7">
    <inertial>
      <origin rpy="0 0 0" xyz="-0.000039 0.000446 -0.003787" />
      <mass value="0.128382" />
      <inertia ixx="6.91193962095496E-05" ixy="1.32697088081543E-10" ixz="8.85654326869473E-10" iyy="6.91388743027247E-05" iyz="2.09447730326603E-11" izz="0.000136853375303708" />
    </inertial>
    <visual>
      <origin rpy="0 0 0" xyz="0 0 0" />
      <geometry>
        <mesh filename="package://daadbot_desc/meshes/Link_7.STL" />
      </geometry>
      <material name="">
        <color rgba="0.329 0.322 0.302 1" />
      </material>
    </visual>
    <collision>
      <origin rpy="0 0 0" xyz="0 0 0" />
      <geometry>
        <mesh filename="package://daadbot_desc/meshes/Link_7.STL" />
      </geometry>
    </collision>
  </link>
  <joint name="joint_7" type="revolute">
    <origin rpy="0 1.5707963267949 0" xyz="-0.0864999036793499 0 0.0280000000004628" />
    <parent link="Link_6" />
    <child link="Link_7" />
    <axis xyz="0 0 -1" />
    <limit effort="15" lower="-3.2" upper="3.2" velocity="1.2" />
    <dynamics damping="0.3" friction="0.0" />
  </joint>
  <link name="endeffector">
    <inertial>
      <origin rpy="0 0 0" xyz="0.011198 -0.013863 0.024599" />
      <mass value="0.155248" />
      <inertia ixx="3.1964247663854E-05" ixy="1.07138220152465E-07" ixz="4.30086683390955E-12" iyy="2.53636526523542E-05" iyz="-9.8230347105402E-08" izz="4.73802906093003E-05" />
    </inertial>
    <visual>
      <origin rpy="0 0 0" xyz="0 0 0" />
      <geometry>
        <mesh filename="package://daadbot_desc/meshes/endeffector.STL" />
      </geometry>
      <material name="">
        <color rgba="1 1 1 1" />
      </material>
    </visual>
    <collision>
      <origin rpy="0 0 0" xyz="0 0 0" />
      <geometry>
        <mesh filename="package://daadbot_desc/meshes/endeffector.STL" />
      </geometry>
    </collision>
  </link>
  <joint name="endeffector_joint" type="fixed">
    <origin rpy="3.14159265357033 0 -3.14159265358979" xyz="0 0 -0.00799999999954315" />
    <parent link="Link_7" />
    <child link="endeffector" />
    <axis xyz="0 0 0" />
  </joint>
  <link name="gear1">
    <inertial>
      <origin rpy="0 0 0" xyz="-0.006223 0.000459 -0.001629" />
      <mass value="0.004867" />
      <inertia ixx="1.81056909473447E-07" ixy="-3.82652046422796E-08" ixz="2.51961968784482E-22" iyy="7.53619126673464E-07" iyz="-2.84205585058754E-24" izz="9.26725977849795E-07" />
    </inertial>
    <visual>
      <origin rpy="0 0 0" xyz="0 0 0" />
      <geometry>
        <mesh filename="package://daadbot_desc/meshes/gear1.STL" />
      </geometry>
      <material name="">
        <color rgba="0.329 0.322 0.302 1" />
      </material>
    </visual>
    <collision>
      <origin rpy="0 0 0" xyz="0 0 0" />
      <geometry>
        <mesh filename="package://daadbot_desc/meshes/gear1.STL" />
      </geometry>
    </collision>
  </link>
  <joint name="gear1_joint" type="revolute">
    <origin rpy="0 1.5707963267949 0" xyz="-0.00375000000000747 -0.013499999998183 0.0376789689084349" />
    <parent link="endeffector" />
    <child link="gear1" />
    <axis xyz="0 0 -1" />
    <limit effort="5" lower="-0.9" upper="0" velocity="0.0" />
    <dynamics damping="0.3" friction="0.0" />
  </joint>
  <link name="gear1_claw">
    <inertial>
      <origin rpy="0 0 0" xyz="0.023297 0.005081 -0.001531" />
      <mass value="0.004034" />
      <inertia ixx="6.08354279127517E-08" ixy="-1.63551242432612E-07" ixz="1.2492000495084E-21" iyy="1.21174464720854E-06" iyz="1.75066929433463E-22" izz="1.26667392866791E-06" />
    </inertial>
    <visual>
      <origin rpy="0 0 0" xyz="0 0 0" />
      <geometry>
        <mesh filename="package://daadbot_desc/meshes/gear1_claw.STL" />
      </geometry>
      <material name="">
        <color rgba="1 1 1 1" />
      </material>
    </visual>
    <collision>
      <origin rpy="0 0 0" xyz="0 0 0" />
      <geometry>
        <mesh filename="package://daadbot_desc/meshes/gear1_claw.STL" />
      </geometry>
    </collision>
  </link>
  <joint name="claw_joint1" type="revolute">
    <origin rpy="3.14159265358979 0 3.14159265358979" xyz="-0.0309835156221249 -0.00101082129116717 0" />
    <parent link="gear1" />
    <child link="gear1_claw" />
    <axis xyz="0 0 1" />
    <limit effort="5" lower="0" upper="0.9" velocity="10" />
    <mimic joint="base_claw_joint1" multiplier="1" offset="0" />
  </joint>
  <link name="gear2_link">
    <inertial>
      <origin rpy="0 0 0" xyz="-0.005078 0.000141 -0.003799" />
      <mass value="0.006158" />
      <inertia ixx="2.15932056711738E-07" ixy="1.70682493885657E-08" ixz="-3.42106080174724E-22" iyy="8.04260102723523E-07" iyz="-8.82852580465177E-23" izz="1.01154671272608E-06" />
    </inertial>
    <visual>
      <origin rpy="0 0 0" xyz="0 0 0" />
      <geometry>
        <mesh filename="package://daadbot_desc/meshes/gear2_link.STL" />
      </geometry>
      <material name="">
        <color rgba="0.329 0.322 0.302 1" />
      </material>
    </visual>
    <collision>
      <origin rpy="0 0 0" xyz="0 0 0" />
      <geometry>
        <mesh filename="package://daadbot_desc/meshes/gear2_link.STL" />
      </geometry>
    </collision>
  </link>
  <joint name="gear2_joint" type="revolute">
    <origin rpy="0 1.5707963267949 0" xyz="-0.00149999999999997 0.0134999999992435 0.0376789689087047" />
    <parent link="endeffector" />
    <child link="gear2_link" />
    <axis xyz="0 0 -1" />
    <limit effort="5" lower="-0.9" upper="0.9" velocity="10" />
    <mimic joint="gear1_joint" multiplier="-1" offset="0" />
  </joint>
  <link name="gear2_claw">
    <inertial>
      <origin rpy="0 0 0" xyz="0.023766 -0.005263 -0.001522" />
      <mass value="0.003904" />
      <inertia ixx="6.0833747461621E-08" ixy="1.63545329654284E-07" ixz="1.24391026243428E-21" iyy="1.21174632765968E-06" iyz="-1.76544893665412E-22" izz="1.26667392866792E-06" />
    </inertial>
    <visual>
      <origin rpy="0 0 0" xyz="0 0 0" />
      <geometry>
        <mesh filename="package://daadbot_desc/meshes/gear2_claw.STL" />
      </geometry>
      <material name="">
        <color rgba="1 1 1 1" />
      </material>
    </visual>
    <collision>
      <origin rpy="0 0 0" xyz="0 0 0" />
      <geometry>
        <mesh filename="package://daadbot_desc/meshes/gear2_claw.STL" />
      </geometry>
    </collision>
  </link>
  <joint name="claw_joint2" type="revolute">
    <origin rpy="-3.14159265358979 0 -3.14159265358979" xyz="-0.0309869843208653 0.000898221965043244 -0.00225000000000025" />
    <parent link="gear2_link" />
    <child link="gear2_claw" />
    <axis xyz="0 0 1" />
    <limit effort="5" lower="-0.9" upper="0" velocity="10" />
    <mimic joint="base_claw_joint2" multiplier="-1" offset="0" />
  </joint>
  <link name="base_claw_link2">
    <inertial>
      <origin rpy="0 0 0" xyz="0.015661 0.000455 0.003869" />
      <mass value="0.001096" />
      <inertia ixx="3.26224455905998E-09" ixy="-4.45032069336059E-09" ixz="1.4396798294983E-22" iyy="1.54535887182587E-07" iyz="2.999466098399E-24" izz="1.56149541453459E-07" />
    </inertial>
    <visual>
      <origin rpy="0 0 0" xyz="0 0 0" />
      <geometry>
        <mesh filename="package://daadbot_desc/meshes/base_claw_link2.STL" />
      </geometry>
      <material name="">
        <color rgba="0.329 0.322 0.302 1" />
      </material>
    </visual>
    <collision>
      <origin rpy="0 0 0" xyz="0 0 0" />
      <geometry>
        <mesh filename="package://daadbot_desc/meshes/base_claw_link2.STL" />
      </geometry>
    </collision>
  </link>
  <joint name="base_claw_joint2" type="revolute">
    <origin rpy="0 1.5707963267949 0" xyz="0.00149999999999995 0.00524999999997672 -0.066078968907985" />
    <parent link="Link_7" />
    <child link="base_claw_link2" />
    <axis xyz="0 0 1" />
    <limit effort="5" lower="0" upper="0.9" velocity="10" />
    <mimic joint="gear1_joint" multiplier="-1" offset="0" />
  </joint>
  <link name="base_claw_link1">
    <inertial>
      <origin rpy="0 0 0" xyz="0.015439 -0.000506 0.003743" />
      <mass value="0.001137" />
      <inertia ixx="3.29655315677714E-09" ixy="4.99941634031931E-09" ixz="2.46402439239775E-22" iyy="1.54501578584872E-07" iyz="-9.36354721708262E-24" izz="1.56149541453461E-07" />
    </inertial>
    <visual>
      <origin rpy="0 0 0" xyz="0 0 0" />
      <geometry>
        <mesh filename="package://daadbot_desc/meshes/base_claw_link1.STL" />
      </geometry>
      <material name="">
        <color rgba="1 1 1 1" />
      </material>
    </visual>
    <collision>
      <origin rpy="0 0 0" xyz="0 0 0" />
      <geometry>
        <mesh filename="package://daadbot_desc/meshes/base_claw_link1.STL" />
      </geometry>
    </collision>
  </link>
  <joint name="base_claw_joint1" type="revolute">
    <origin rpy="0 1.5707963267949 0" xyz="0.00149999999999995 -0.00525000000002329 -0.066078968907985" />
    <parent link="Link_7" />
    <child link="base_claw_link1" />
    <axis xyz="0 0 -1" />
    <limit effort="5" lower="0" upper="0.9" velocity="10" />
    <mimic joint="gear1_joint" multiplier="-1" offset="0" />
  </joint>
</robot>